Workbook

Sheet Assumptions
A1: M&A Financial Model - CloudCore Inc. / DataStream Analytics
A2: Asssumptions
B3: Base Case
A4: Acquiror – CloudCore Inc.
A5: Revenue CloudCore ($M) | B5: =480 -> 480
A6: EBITDA margin | B6: 0.22
A7: D&A standalone ($M) | B7: =18 -> 18 | D7: Estimated; ~3.75% of revenue
A8: Net Debt Pre deal ($M) | B8: =120 -> 120
A9: Pre-deal Interest Rate | B9: 0.05 | D9: Existing term loan @ 5%
A10: Tax Rate | B10: 0.25 | D10: Blended US federal + state estimate
A11: Diluted shares outstanding ($M) | B11: 82
A12: CloudCore share price ($) | B12: 38
A13: CloudCore revenue growth (YoY) | B13: 0.05 | D13: Reference price for stock consideration
A15: Target – DataStream Analytics
A16: ARR LTM ($M) | B16: 95
A17: ARR growth rate (YoY) | B17: 0.38
A18: Gross margin | B18: 0.74
A19: OpEx as % of revenue | B19: 0.54
A20: D&A target standalone ($M) | B20: 5 | D20: Estimated
A21: Net Revenue Retention | B21: 1.18
A23: Deal Structure
A24: Acquisition Price ($M) | B24: 570 | D24: 6.0x ARR; ~17x fwd EBITDA
A25: Stock Consideration (%) | B25: 0.4 | D25: 40% stock / 60% cash+debt
A26: New Term Loan B ($M) | B26: 200 | D26: 5-year TLB
A27: New Debt Interest Rate | B27: 0.075 | D27: SOFR + 250bps spread
A28: Transaction Fees (% of price) | B28: 0.02 | D28: Advisory + Legal + Financing fees
A29: PPA Intangibles (% of price) | B29: 0.2 | D29: Customer relationships + technology IP
A30: PPA amortization life (yrs) | B30: 6 | D30: Straight-line over 6 yrs
A32: Synergies
A33: Revenue Synergies – fully ramped ($M ARR) | B33: 42 | D33: Cross-sell + upsell; $28M+$14M
A34: Cost Synergies – fully ramped ($M OpEx) | B34: 14 | D34: Infrastructure + G&A overlap
A35: Synergies realized in Year 1 (%) | B35: 0.5 | D35: Ramp assumption
A36: Synergies realized in Year 2 (%) | B36: 0.8 | D36: Ramp assumption
A37: Synergies realized in Year 3 (%) | B37: 1 | D37: Fully Ramped yr3
A38: Integration costs – one-time ($M) | B38: 22 | D38: Systems + Talent retention + rebrand

Sheet EPS Model
A1: EBS Accretion/Dilution Model – CloudCore acquires DataStream
A2: Pro forma EPS Bridge | Year 1-Year 3
B4: Year 1 ($M) | C4: Year 2 ($M) | D4: Year 3 ($M)
A5: BLOCK 1 – CloudCore Standalone (pre-deal)
A6: Revenue CloudCore | B6: =Assumptions!$B5*(1+Assumptions!B13) -> 504 | C6: =B6*(1+Assumptions!B13) -> 529.2 | D6: =C6*(1+Assumptions!B13) -> 555.66
A7: EBITDA (22%) | B7: =B6*(Assumptions!B6) -> 110.88 | C7: =C6*(Assumptions!B6) -> 116.424 | D7: =D6*(Assumptions!B6) -> 122.2452
A8: D&A standalone | B8: =-Assumptions!B7 -> -18 | C8: =-Assumptions!B7 -> -18 | D8: =-Assumptions!B7 -> -18
A9: EBIT | B9: =B7+B8 -> 92.88 | C9: =C7+C8 -> 98.424 | D9: =D7+D8 -> 104.2452
A10: Interest expense | B10: =-Assumptions!B8*Assumptions!B9 -> -6 | C10: =-Assumptions!B8*Assumptions!B9 -> -6 | D10: =-Assumptions!B8*Assumptions!B9 -> -6
A11: EBT | B11: =B9+B10 -> 86.88 | C11: =C9+C10 -> 92.424 | D11: =D9+D10 -> 98.2452
A12: Taxes | B12: =B11*(-Assumptions!B10) -> -21.72 | C12: =C11*(-Assumptions!B10) -> -23.106 | D12: =D11*(-Assumptions!B10) -> -24.5613
A13: Net income standalone | B13: =B11+B12 -> 65.16 | C13: =C11+C12 -> 69.318 | D13: =D11+D12 -> 73.6839
A14: Diluted shares outstanding | B14: =82 -> 82 | C14: =82 -> 82 | D14: =82 -> 82
A15: EPS standalone | B15: =B13/B14 -> 0.79463415 | C15: =C13/C14 -> 0.84534146 | D15: =D13/D14 -> 0.89858415
A17: BLOCK 2 – Sources & Uses
A18: New Term Loan B | B18: =200 -> 200
A19: CloudCore Cash | B19: =B24-B18-B20 -> 153.4
A20: Stock Consideration(40%) | B20: =570*0.4 -> 228
A21: Total Sources | B21: =SUM(B18:B20) -> 581.4
A22: Acquisition Price | B22: =570 -> 570
A23: Transaction fees | B23: =B22*0.02 -> 11.4
A24: Total Uses | B24: =B22+B23 -> 581.4
A25: Sources = Uses | B25: =B21=B24 -> TRUE
A27: BLOCK 3 – Share Dilution
A28: Stock Consideration | B28: =B20 -> 228
A29: PPS CloudCore | B29: =Assumptions!B12 -> 38
A30: New Shares | B30: =B28/B29 -> 6
A31: Shares Prev. Outstanding | B31: ='EPS Model'!B14 -> 82
A32: Pro forma shares | B32: =B31+B30 -> 88
A34: BLOCK 4 – Deal Costs (reduce earnings)
A35: Interest – new Term Loan B | B35: =-Assumptions!B26*Assumptions!B27 -> -15 | C35: =-Assumptions!B26*Assumptions!B27 -> -15 | D35: =-Assumptions!B26*Assumptions!B27 -> -15
A36: PPA Amortization (intangibles) | B36: =-(Assumptions!B24*Assumptions!B29)/Assumptions!B30 -> -19 | C36: =-(Assumptions!B24*Assumptions!B29)/Assumptions!B30 -> -19 | D36: =-(Assumptions!B24*Assumptions!B29)/Assumptions!B30 -> -19
A37: Transaction fees (one time, Yr1) | B37: =-Assumptions!B24*Assumptions!B28 -> -11.4
A38: Total deal costs pre-tax | B38: =SUM(B35:B37) -> -45.4 | C38: =SUM(C35:C37) -> -34 | D38: =SUM(D35:D37) -> -34
A39: Tax shield on deal costs | B39: =-B38*Assumptions!B10 -> 11.35 | C39: =-C38*Assumptions!B10 -> 8.5 | D39: =-D38*Assumptions!B10 -> 8.5
A40: Deal costs after tax | B40: =B38+B39 -> -34.05 | C40: =C38+C39 -> -25.5 | D40: =D38+D39 -> -25.5
A42: BLOCK 5 – DataStream Earnings Contribution
A43: ARR (start of year) | B43: =Assumptions!B16*(1+Assumptions!B17) -> 131.1 | C43: =B43*(1+Assumptions!B17) -> 180.918 | D43: =C43*(1+Assumptions!B17) -> 249.66684
A44: Gross profit | B44: =B43*Assumptions!B18 -> 97.014 | C44: =C43*Assumptions!B18 -> 133.87932 | D44: =D43*Assumptions!B18 -> 184.75346
A45: OpEx | B45: =-B43*Assumptions!B19 -> -70.794 | C45: =-C43*Assumptions!B19 -> -97.69572 | D45: =-D43*Assumptions!B19 -> -134.82009
...

Sheet Sensitivity
A1: Sensitivity Analysis – Accretion/Dilution (%)
A2: Year 3 EPS % change vs. standalone | Acquisition price vs. synergy realization
A5: Acq. Price / Syns realized | B5: 0 | C5: 0.25 | D5: 0.5 | E5: 0.75 | F5: 1
A6: 490 | B6: =(((((((Assumptions!B5*(1+Assumptions!B13)^3)*Assumptions!B6)-Assumptions!B7-Assumptions!B8*Assumptions!B9)*(1-Assumptions!B10))+((((Assumptions!B16*(1+Assumptions!B17)^3)*Assumptions!B18)+(-(Assumptions!B16*(1+Assumptions!B17)^3)*Assumptions!B19)-Assumptions!B20+(Assumptions!B34*B5))*(1-Assumptions!B10))+(Assumptions!B33*B5*(1-Assumptions!B10))+(((-Assumptions!B26*Assumptions!B27)+(-((A6*Assumptions!B29)/Assumptions!B30)))+(-((-Assumptions!B26*Assumptions!B27)+(-((A6*Assumptions!B29)/Assumptions!B30)))*Assumptions!B10)))/(Assumptions!B11+(A6*Assumptions!B25/Assumptions!B12)))-(((((Assumptions!B5*(1+Assumptions!B13)^3)*Assumptions!B6)-Assumptions!B7-Assumptions!B8*Assumptions!B9)*(1-Assumptions!B10))/Assumptions!B11))/(((((Assumptions!B5*(1+Assumptions!B13)^3)*Assumptions!B6)-Assumptions!B7-Assumptions!B8*Assumptions!B9)*(1-Assumptions!B10))/Assumptions!B11) -> 0.071058679 | C6: =(((((((Assumptions!B5*(1+Assumptions!B13)^3)*Assumptions!B6)-Assumptions!B7-Assumptions!B8*Assumptions!B9)*(1-Assumptions!B10))+((((Assumptions!B16*(1+Assumptions!B17)^3)*Assumptions!B18)+(-(Assumptions!B16*(1+Assumptions!B17)^3)*Assumptions!B19)-Assumptions!B20+(Assumptions!B34*C5))*(1-Assumptions!B10))+(Assumptions!B33*C5*(1-Assumptions!B10))+(((-Assumptions!B26*Assumptions!B27)+(-((A6*Assumptions!B29)/Assumptions!B30)))+(-((-Assumptions!B26*Assumptions!B27)+(-((A6*Assumptions!B29)/Assumptions!B30)))*Assumptions!B10)))/(Assumptions!B11+(A6*Assumptions!B25/Assumptions!B12)))-(((((Assumptions!B5*(1+Assumptions!B13)^3)*Assumptions!B6)-Assumptions!B7-Assumptions!B8*Assumptions!B9)*(1-Assumptions!B10))/Assumptions!B11))/(((((Assumptions!B5*(1+Assumptions!B13)^3)*Assumptions!B6)-Assumptions!B7-Assumptions!B8*Assumptions!B9)*(1-Assumptions!B10))/Assumptions!B11) -> 0.20512627 | D6: =(((((((Assumptions!B5*(1+Assumptions!B13)^3)*Assumptions!B6)-Assumptions!B7-Assumptions!B8*Assumptions!B9)*(1-Assumptions!B10))+((((Assumptions!B16*(1+Assumptions!B17)^3)*Assumptions!B18)+(-(Assumptions!B16*(1+Assumptions!B17)^3)*Assumptions!B19)-Assumptions!B20+(Assumptions!B34*D5))*(1-Assumptions!B10))+(Assumptions!B33*D5*(1-Assumptions!B10))+(((-Assumptions!B26*Assumptions!B27)+(-((A6*Assumptions!B29)/Assumptions!B30)))+(-((-Assumptions!B26*Assumptions!B27)+(-((A6*Assumptions!B29)/Assumptions!B30)))*Assumptions!B10)))/(Assumptions!B11+(A6*Assumptions!B25/Assumptions!B12)))-(((((Assumptions!B5*(1+Assumptions!B13)^3)*Assumptions!B6)-Assumptions!B7-Assumptions!B8*Assumptions!B9)*(1-Assumptions!B10))/Assumptions!B11))/(((((Assumptions!B5*(1+Assumptions!B13)^3)*Assumptions!B6)-Assumptions!B7-Assumptions!B8*Assumptions!B9)*(1-Assumptions!B10))/Assumptions!B11) -> 0.33919387 | E6: =(((((((Assumptions!B5*(1+Assumptions!B13)^3)*Assumptions!B6)-Assumptions!B7-Assumptions!B8*Assumptions!B9)*(1-Assumptions!B10))+((((Assumptions!B16*(1+Assumptions!B17)^3)*Assumptions!B18)+(-(Assumptions!B16*(1+Assumptions!B17)^3)*Assumptions!B19)-Assumptions!B20+(Assumptions!B34*E5))*(1-Assumptions!B10))+(Assumptions!B33*E5*(1-Assumptions!B10))+(((-Assumptions!B26*Assumptions!B27)+(-((A6*Assumptions!B29)/Assumptions!B30)))+(-((-Assumptions!B26*Assumptions!B27)+(-((A6*Assumptions!B29)/Assumptions!B30)))*Assumptions!B10)))/(Assumptions!B11+(A6*Assumptions!B25/Assumptions!B12)))-(((((Assumptions!B5*(1+Assumptions!B13)^3)*Assumptions!B6)-Assumptions!B7-Assumptions!B8*Assumptions!B9)*(1-Assumptions!B10))/Assumptions!B11))/(((((Assumptions!B5*(1+Assumptions!B13)^3)*Assumptions!B6)-Assumptions!B7-Assumptions!B8*Assumptions!B9)*(1-Assumptions!B10))/Assumptions!B11) -> 0.47326146 | F6: =(((((((Assumptions!B5*(1+Assumptions!B13)^3)*Assumptions!B6)-Assumptions!B7-Assumptions!B8*Assumptions!B9)*(1-Assumptions!B10))+((((Assumptions!B16*(1+Assumptions!B17)^3)*Assumptions!B18)+(-(Assumptions!B16*(1+Assumptions!B17)^3)*Assumptions!B19)-Assumptions!B20+(Assumptions!B34*F5))*(1-Assumptions!B10))+(Assumptions!B33*F5*(1-Assumptions!B10))+(((-Assumptions!B26*Assumptions!B27)+(-((A6*Assumptions!B29)/Assumptions!B30)))+(-((-Assumptions!B26*Assumptions!B27)+(-((A6*Assumptions!B29)/Assumptions!B30)))*Assumptions!B10)))/(Assumptions!B11+(A6*Assumptions!B25/Assumptions!B12)))-(((((Assumptions!B5*(1+Assumptions!B13)^3)*Assumptions!B6)-Assumptions!B7-Assumptions!B8*Assumptions!B9)*(1-Assumptions!B10))/Assumptions!B11))/(((((Assumptions!B5*(1+Assumptions!B13)^3)*Assumptions!B6)-Assumptions!B7-Assumptions!B8*Assumptions!B9)*(1-Assumptions!B10))/Assumptions!B11) -> 0.60732906
A7: 520 | B7: =(((((((Assumptions!B5*(1+Assumptions!B13)^3)*Assumptions!B6)-Assumptions!B7-Assumptions!B8*Assumptions!B9)*(1-Assumptions!B10))+((((Assumptions!B16*(1+Assumptions!B17)^3)*Assumptions!B18)+(-(Assumptions!B16*(1+Assumptions!B17)^3)*Assumptions!B19)-Assumptions!B20+(Assumptions!B34*B5))*(1-Assumptions!B10))+(Assumptions!B33*B5*(1-Assumptions!B10))+(((-Assumptions!B26*Assumptions!B27)+(-((A7*Assumptions!B29)/Assumptions!B30)))+(-((-Assumptions!B26*Assumptions!B27)+(-((A7*Assumptions!B29)/Assumptions!B30)))*Assumptions!B10)))/(Assumptions!B11+(A7*Assumptions!B25/Assumptions!B12)))-(((((Assumptions!B5*(1+Assumptions!B13)^3)*Assumptions!B6)-Assumptions!B7-Assumptions!B8*Assumptions!B9)*(1-Assumptions!B10))/Assumptions!B11))/(((((Assumptions!B5*(1+Assumptions!B13)^3)*Assumptions!B6)-Assumptions!B7-Assumptions!B8*Assumptions!B9)*(1-Assumptions!B10))/Assumptions!B11) -> 0.057650356 | C7: =(((((((Assumptions!B5*(1+Assumptions!B13)^3)*Assumptions!B6)-Assumptions!B7-Assumptions!B8*Assumptions!B9)*(1-Assumptions!B10))+((((Assumptions!B16*(1+Assumptions!B17)^3)*Assumptions!B18)+(-(Assumptions!B16*(1+Assumptions!B17)^3)*Assumptions!B19)-Assumptions!B20+(Assumptions!B34*C5))*(1-Assumptions!B10))+(Assumptions!B33*C5*(1-Assumptions!B10))+(((-Assumptions!B26*Assumptions!B27)+(-((A7*Assumptions!B29)/Assumptions!B30)))+(-((-Assumptions!B26*Assumptions!B27)+(-((A7*Assumptions!B29)/Assumptions!B30)))*Assumptions!B10)))/(Assumptions!B11+(A7*Assumptions!B25/Assumptions!B12)))-(((((Assumptions!B5*(1+Assumptions!B13)^3)*Assumptions!B6)-Assumptions!B7-Assumptions!B8*Assumptions!B9)*(1-Assumptions!B10))/Assumptions!B11))/(((((Assumptions!B5*(1+Assumptions!B13)^3)*Assumptions!B6)-Assumptions!B7-Assumptions!B8*Assumptions!B9)*(1-Assumptions!B10))/Assumptions!B11) -> 0.19123395 | D7: =(((((((Assumptions!B5*(1+Assumptions!B13)^3)*Assumptions!B6)-Assumptions!B7-Assumptions!B8*Assumptions!B9)*(1-Assumptions!B10))+((((Assumptions!B16*(1+Assumptions!B17)^3)*Assumptions!B18)+(-(Assumptions!B16*(1+Assumptions!B17)^3)*Assumptions!B19)-Assumptions!B20+(Assumptions!B34*D5))*(1-Assumptions!B10))+(Assumptions!B33*D5*(1-Assumptions!B10))+(((-Assumptions!B26*Assumptions!B27)+(-((A7*Assumptions!B29)/Assumptions!B30)))+(-((-Assumptions!B26*Assumptions!B27)+(-((A7*Assumptions!B29)/Assumptions!B30)))*Assumptions!B10)))/(Assumptions!B11+(A7*Assumptions!B25/Assumptions!B12)))-(((((Assumptions!B5*(1+Assumptions!B13)^3)*Assumptions!B6)-Assumptions!B7-Assumptions!B8*Assumptions!B9)*(1-Assumptions!B10))/Assumptions!B11))/(((((Assumptions!B5*(1+Assumptions!B13)^3)*Assumptions!B6)-Assumptions!B7-Assumptions!B8*Assumptions!B9)*(1-Assumptions!B10))/Assumptions!B11) -> 0.32481755 | E7: =(((((((Assumptions!B5*(1+Assumptions!B13)^3)*Assumptions!B6)-Assumptions!B7-Assumptions!B8*Assumptions!B9)*(1-Assumptions!B10))+((((Assumptions!B16*(1+Assumptions!B17)^3)*Assumptions!B18)+(-(Assumptions!B16*(1+Assumptions!B17)^3)*Assumptions!B19)-Assumptions!B20+(Assumptions!B34*E5))*(1-Assumptions!B10))+(Assumptions!B33*E5*(1-Assumptions!B10))+(((-Assumptions!B26*Assumptions!B27)+(-((A7*Assumptions!B29)/Assumptions!B30)))+(-((-Assumptions!B26*Assumptions!B27)+(-((A7*Assumptions!B29)/Assumptions!B30)))*Assumptions!B10)))/(Assumptions!B11+(A7*Assumptions!B25/Assumptions!B12)))-(((((Assumptions!B5*(1+Assumptions!B13)^3)*Assumptions!B6)-Assumptions!B7-Assumptions!B8*Assumptions!B9)*(1-Assumptions!B10))/Assumptions!B11))/(((((Assumptions!B5*(1+Assumptions!B13)^3)*Assumptions!B6)-Assumptions!B7-Assumptions!B8*Assumptions!B9)*(1-Assumptions!B10))/Assumptions!B11) -> 0.45840114 | F7: =(((((((Assumptions!B5*(1+Assumptions!B13)^3)*Assumptions!B6)-Assumptions!B7-Assumptions!B8*Assumptions!B9)*(1-Assumptions!B10))+((((Assumptions!B16*(1+Assumptions!B17)^3)*Assumptions!B18)+(-(Assumptions!B16*(1+Assumptions!B17)^3)*Assumptions!B19)-Assumptions!B20+(Assumptions!B34*F5))*(1-Assumptions!B10))+(Assumptions!B33*F5*(1-Assumptions!B10))+(((-Assumptions!B26*Assumptions!B27)+(-((A7*Assumptions!B29)/Assumptions!B30)))+(-((-Assumptions!B26*Assumptions!B27)+(-((A7*Assumptions!B29)/Assumptions!B30)))*Assumptions!B10)))/(Assumptions!B11+(A7*Assumptions!B25/Assumptions!B12)))-(((((Assumptions!B5*(1+Assumptions!B13)^3)*Assumptions!B6)-Assumptions!B7-Assumptions!B8*Assumptions!B9)*(1-Assumptions!B10))/Assumptions!B11))/(((((Assumptions!B5*(1+Assumptions!B13)^3)*Assumptions!B6)-Assumptions!B7-Assumptions!B8*Assumptions!B9)*(1-Assumptions!B10))/Assumptions!B11) -> 0.59198474
A8: 550 | B8: =(((((((Assumptions!B5*(1+Assumptions!B13)^3)*Assumptions!B6)-Assumptions!B7-Assumptions!B8*Assumptions!B9)*(1-Assumptions!B10))+((((Assumptions!B16*(1+Assumptions!B17)^3)*Assumptions!B18)+(-(Assumptions!B16*(1+Assumptions!B17)^3)*Assumptions!B19)-Assumptions!B20+(Assumptions!B34*B5))*(1-Assumptions!B10))+(Assumptions!B33*B5*(1-Assumptions!B10))+(((-Assumptions!B26*Assumptions!B27)+(-((A8*Assumptions!B29)/Assumptions!B30)))+(-((-Assumptions!B26*Assumptions!B27)+(-((A8*Assumptions!B29)/Assumptions!B30)))*Assumptions!B10)))/(Assumptions!B11+(A8*Assumptions!B25/Assumptions!B12)))-(((((Assumptions!B5*(1+Assumptions!B13)^3)*Assumptions!B6)-Assumptions!B7-Assumptions!B8*Assumptions!B9)*(1-Assumptions!B10))/Assumptions!B11))/(((((Assumptions!B5*(1+Assumptions!B13)^3)*Assumptions!B6)-Assumptions!B7-Assumptions!B8*Assumptions!B9)*(1-Assumptions!B10))/Assumptions!B11) -> 0.044338496 | C8: =(((((((Assumptions!B5*(1+Assumptions!B13)^3)*Assumptions!B6)-Assumptions!B7-Assumptions!B8*Assumptions!B9)*(1-Assumptions!B10))+((((Assumptions!B16*(1+Assumptions!B17)^3)*Assumptions!B18)+(-(Assumptions!B16*(1+Assumptions!B17)^3)*Assumptions!B19)-Assumptions!B20+(Assumptions!B34*C5))*(1-Assumptions!B10))+(Assumptions!B33*C5*(1-Assumptions!B10))+(((-Assumptions!B26*Assumptions!B27)+(-((A8*Assumptions!B29)/Assumptions!B30)))+(-((-Assumptions!B26*Assumptions!B27)+(-((A8*Assumptions!B29)/Assumptions!B30)))*Assumptions!B10)))/(Assumptions!B11+(A8*Assumptions!B25/Assumptions!B12)))-(((((Assumptions!B5*(1+Assumptions!B13)^3)*Assumptions!B6)-Assumptions!B7-Assumptions!B8*Assumptions!B9)*(1-Assumptions!B10))/Assumptions!B11))/(((((Assumptions!B5*(1+Assumptions!B13)^3)*Assumptions!B6)-Assumptions!B7-Assumptions!B8*Assumptions!B9)*(1-Assumptions!B10))/Assumptions!B11) -> 0.17744157 | D8: =(((((((Assumptions!B5*(1+Assumptions!B13)^3)*Assumptions!B6)-Assumptions!B7-Assumptions!B8*Assumptions!B9)*(1-Assumptions!B10))+((((Assumptions!B16*(1+Assumptions!B17)^3)*Assumptions!B18)+(-(Assumptions!B16*(1+Assumptions!B17)^3)*Assumptions!B19)-Assumptions!B20+(Assumptions!B34*D5))*(1-Assumptions!B10))+(Assumptions!B33*D5*(1-Assumptions!B10))+(((-Assumptions!B26*Assumptions!B27)+(-((A8*Assumptions!B29)/Assumptions!B30)))+(-((-Assumptions!B26*Assumptions!B27)+(-((A8*Assumptions!B29)/Assumptions!B30)))*Assumptions!B10)))/(Assumptions!B11+(A8*Assumptions!B25/Assumptions!B12)))-(((((Assumptions!B5*(1+Assumptions!B13)^3)*Assumptions!B6)-Assumptions!B7-Assumptions!B8*Assumptions!B9)*(1-Assumptions!B10))/Assumptions!B11))/(((((Assumptions!B5*(1+Assumptions!B13)^3)*Assumptions!B6)-Assumptions!B7-Assumptions!B8*Assumptions!B9)*(1-Assumptions!B10))/Assumptions!B11) -> 0.31054465 | E8: =(((((((Assumptions!B5*(1+Assumptions!B13)^3)*Assumptions!B6)-Assumptions!B7-Assumptions!B8*Assumptions!B9)*(1-Assumptions!B10))+((((Assumptions!B16*(1+Assumptions!B17)^3)*Assumptions!B18)+(-(Assumptions!B16*(1+Assumptions!B17)^3)*Assumptions!B19)-Assumptions!B20+(Assumptions!B34*E5))*(1-Assumptions!B10))+(Assumptions!B33*E5*(1-Assumptions!B10))+(((-Assumptions!B26*Assumptions!B27)+(-((A8*Assumptions!B29)/Assumptions!B30)))+(-((-Assumptions!B26*Assumptions!B27)+(-((A8*Assumptions!B29)/Assumptions!B30)))*Assumptions!B10)))/(Assumptions!B11+(A8*Assumptions!B25/Assumptions!B12)))-(((((Assumptions!B5*(1+Assumptions!B13)^3)*Assumptions!B6)-Assumptions!B7-Assumptions!B8*Assumptions!B9)*(1-Assumptions!B10))/Assumptions!B11))/(((((Assumptions!B5*(1+Assumptions!B13)^3)*Assumptions!B6)-Assumptions!B7-Assumptions!B8*Assumptions!B9)*(1-Assumptions!B10))/Assumptions!B11) -> 0.44364773 | F8: =(((((((Assumptions!B5*(1+Assumptions!B13)^3)*Assumptions!B6)-Assumptions!B7-Assumptions!B8*Assumptions!B9)*(1-Assumptions!B10))+((((Assumptions!B16*(1+Assumptions!B17)^3)*Assumptions!B18)+(-(Assumptions!B16*(1+Assumptions!B17)^3)*Assumptions!B19)-Assumptions!B20+(Assumptions!B34*F5))*(1-Assumptions!B10))+(Assumptions!B33*F5*(1-Assumptions!B10))+(((-Assumptions!B26*Assumptions!B27)+(-((A8*Assumptions!B29)/Assumptions!B30)))+(-((-Assumptions!B26*Assumptions!B27)+(-((A8*Assumptions!B29)/Assumptions!B30)))*Assumptions!B10)))/(Assumptions!B11+(A8*Assumptions!B25/Assumptions!B12)))-(((((Assumptions!B5*(1+Assumptions!B13)^3)*Assumptions!B6)-Assumptions!B7-Assumptions!B8*Assumptions!B9)*(1-Assumptions!B10))/Assumptions!B11))/(((((Assumptions!B5*(1+Assumptions!B13)^3)*Assumptions!B6)-Assumptions!B7-Assumptions!B8*Assumptions!B9)*(1-Assumptions!B10))/Assumptions!B11) -> 0.57675081
A9: 570 | B9: =(((((((Assumptions!B5*(1+Assumptions!B13)^3)*Assumptions!B6)-Assumptions!B7-Assumptions!B8*Assumptions!B9)*(1-Assumptions!B10))+((((Assumptions!B16*(1+Assumptions!B17)^3)*Assumptions!B18)+(-(Assumptions!B16*(1+Assumptions!B17)^3)*Assumptions!B19)-Assumptions!B20+(Assumptions!B34*B5))*(1-Assumptions!B10))+(Assumptions!B33*B5*(1-Assumptions!B10))+(((-Assumptions!B26*Assumptions!B27)+(-((A9*Assumptions!B29)/Assumptions!B30)))+(-((-Assumptions!B26*Assumptions!B27)+(-((A9*Assumptions!B29)/Assumptions!B30)))*Assumptions!B10)))/(Assumptions!B11+(A9*Assumptions!B25/Assumptions!B12)))-(((((Assumptions!B5*(1+Assumptions!B13)^3)*Assumptions!B6)-Assumptions!B7-Assumptions!B8*Assumptions!B9)*(1-Assumptions!B10))/Assumptions!B11))/(((((Assumptions!B5*(1+Assumptions!B13)^3)*Assumptions!B6)-Assumptions!B7-Assumptions!B8*Assumptions!B9)*(1-Assumptions!B10))/Assumptions!B11) -> 0.035517 | C9: =(((((((Assumptions!B5*(1+Assumptions!B13)^3)*Assumptions!B6)-Assumptions!B7-Assumptions!B8*Assumptions!B9)*(1-Assumptions!B10))+((((Assumptions!B16*(1+Assumptions!B17)^3)*Assumptions!B18)+(-(Assumptions!B16*(1+Assumptions!B17)^3)*Assumptions!B19)-Assumptions!B20+(Assumptions!B34*C5))*(1-Assumptions!B10))+(Assumptions!B33*C5*(1-Assumptions!B10))+(((-Assumptions!B26*Assumptions!B27)+(-((A9*Assumptions!B29)/Assumptions!B30)))+(-((-Assumptions!B26*Assumptions!B27)+(-((A9*Assumptions!B29)/Assumptions!B30)))*Assumptions!B10)))/(Assumptions!B11+(A9*Assumptions!B25/Assumptions!B12)))-(((((Assumptions!B5*(1+Assumptions!B13)^3)*Assumptions!B6)-Assumptions!B7-Assumptions!B8*Assumptions!B9)*(1-Assumptions!B10))/Assumptions!B11))/(((((Assumptions!B5*(1+Assumptions!B13)^3)*Assumptions!B6)-Assumptions!B7-Assumptions!B8*Assumptions!B9)*(1-Assumptions!B10))/Assumptions!B11) -> 0.16830165 | D9: =(((((((Assumptions!B5*(1+Assumptions!B13)^3)*Assumptions!B6)-Assumptions!B7-Assumptions!B8*Assumptions!B9)*(1-Assumptions!B10))+((((Assumptions!B16*(1+Assumptions!B17)^3)*Assumptions!B18)+(-(Assumptions!B16*(1+Assumptions!B17)^3)*Assumptions!B19)-Assumptions!B20+(Assumptions!B34*D5))*(1-Assumptions!B10))+(Assumptions!B33*D5*(1-Assumptions!B10))+(((-Assumptions!B26*Assumptions!B27)+(-((A9*Assumptions!B29)/Assumptions!B30)))+(-((-Assumptions!B26*Assumptions!B27)+(-((A9*Assumptions!B29)/Assumptions!B30)))*Assumptions!B10)))/(Assumptions!B11+(A9*Assumptions!B25/Assumptions!B12)))-(((((Assumptions!B5*(1+Assumptions!B13)^3)*Assumptions!B6)-Assumptions!B7-Assumptions!B8*Assumptions!B9)*(1-Assumptions!B10))/Assumptions!B11))/(((((Assumptions!B5*(1+Assumptions!B13)^3)*Assumptions!B6)-Assumptions!B7-Assumptions!B8*Assumptions!B9)*(1-Assumptions!B10))/Assumptions!B11) -> 0.3010863 | E9: =(((((((Assumptions!B5*(1+Assumptions!B13)^3)*Assumptions!B6)-Assumptions!B7-Assumptions!B8*Assumptions!B9)*(1-Assumptions!B10))+((((Assumptions!B16*(1+Assumptions!B17)^3)*Assumptions!B18)+(-(Assumptions!B16*(1+Assumptions!B17)^3)*Assumptions!B19)-Assumptions!B20+(Assumptions!B34*E5))*(1-Assumptions!B10))+(Assumptions!B33*E5*(1-Assumptions!B10))+(((-Assumptions!B26*Assumptions!B27)+(-((A9*Assumptions!B29)/Assumptions!B30)))+(-((-Assumptions!B26*Assumptions!B27)+(-((A9*Assumptions!B29)/Assumptions!B30)))*Assumptions!B10)))/(Assumptions!B11+(A9*Assumptions!B25/Assumptions!B12)))-(((((Assumptions!B5*(1+Assumptions!B13)^3)*Assumptions!B6)-Assumptions!B7-Assumptions!B8*Assumptions!B9)*(1-Assumptions!B10))/Assumptions!B11))/(((((Assumptions!B5*(1+Assumptions!B13)^3)*Assumptions!B6)-Assumptions!B7-Assumptions!B8*Assumptions!B9)*(1-Assumptions!B10))/Assumptions!B11) -> 0.43387095 | F9: =(((((((Assumptions!B5*(1+Assumptions!B13)^3)*Assumptions!B6)-Assumptions!B7-Assumptions!B8*Assumptions!B9)*(1-Assumptions!B10))+((((Assumptions!B16*(1+Assumptions!B17)^3)*Assumptions!B18)+(-(Assumptions!B16*(1+Assumptions!B17)^3)*Assumptions!B19)-Assumptions!B20+(Assumptions!B34*F5))*(1-Assumptions!B10))+(Assumptions!B33*F5*(1-Assumptions!B10))+(((-Assumptions!B26*Assumptions!B27)+(-((A9*Assumptions!B29)/Assumptions!B30)))+(-((-Assumptions!B26*Assumptions!B27)+(-((A9*Assumptions!B29)/Assumptions!B30)))*Assumptions!B10)))/(Assumptions!B11+(A9*Assumptions!B25/Assumptions!B12)))-(((((Assumptions!B5*(1+Assumptions!B13)^3)*Assumptions!B6)-Assumptions!B7-Assumptions!B8*Assumptions!B9)*(1-Assumptions!B10))/Assumptions!B11))/(((((Assumptions!B5*(1+Assumptions!B13)^3)*Assumptions!B6)-Assumptions!B7-Assumptions!B8*Assumptions!B9)*(1-Assumptions!B10))/Assumptions!B11) -> 0.5666556
A10: 600 | B10: =(((((((Assumptions!B5*(1+Assumptions!B13)^3)*Assumptions!B6)-Assumptions!B7-Assumptions!B8*Assumptions!B9)*(1-Assumptions!B10))+((((Assumptions!B16*(1+Assumptions!B17)^3)*Assumptions!B18)+(-(Assumptions!B16*(1+Assumptions!B17)^3)*Assumptions!B19)-Assumptions!B20+(Assumptions!B34*B5))*(1-Assumptions!B10))+(Assumptions!B33*B5*(1-Assumptions!B10))+(((-Assumptions!B26*Assumptions!B27)+(-((A10*Assumptions!B29)/Assumptions!B30)))+(-((-Assumptions!B26*Assumptions!B27)+(-((A10*Assumptions!B29)/Assumptions!B30)))*Assumptions!B10)))/(Assumptions!B11+(A10*Assumptions!B25/Assumptions!B12)))-(((((Assumptions!B5*(1+Assumptions!B13)^3)*Assumptions!B6)-Assumptions!B7-Assumptions!B8*Assumptions!B9)*(1-Assumptions!B10))/Assumptions!B11))/(((((Assumptions!B5*(1+Assumptions!B13)^3)*Assumptions!B6)-Assumptions!B7-Assumptions!B8*Assumptions!B9)*(1-Assumptions!B10))/Assumptions!B11) -> 0.022363613 | C10: =(((((((Assumptions!B5*(1+Assumptions!B13)^3)*Assumptions!B6)-Assumptions!B7-Assumptions!B8*Assumptions!B9)*(1-Assumptions!B10))+((((Assumptions!B16*(1+Assumptions!B17)^3)*Assumptions!B18)+(-(Assumptions!B16*(1+Assumptions!B17)^3)*Assumptions!B19)-Assumptions!B20+(Assumptions!B34*C5))*(1-Assumptions!B10))+(Assumptions!B33*C5*(1-Assumptions!B10))+(((-Assumptions!B26*Assumptions!B27)+(-((A10*Assumptions!B29)/Assumptions!B30)))+(-((-Assumptions!B26*Assumptions!B27)+(-((A10*Assumptions!B29)/Assumptions!B30)))*Assumptions!B10)))/(Assumptions!B11+(A10*Assumptions!B25/Assumptions!B12)))-(((((Assumptions!B5*(1+Assumptions!B13)^3)*Assumptions!B6)-Assumptions!B7-Assumptions!B8*Assumptions!B9)*(1-Assumptions!B10))/Assumptions!B11))/(((((Assumptions!B5*(1+Assumptions!B13)^3)*Assumptions!B6)-Assumptions!B7-Assumptions!B8*Assumptions!B9)*(1-Assumptions!B10))/Assumptions!B11) -> 0.15467347 | D10: =(((((((Assumptions!B5*(1+Assumptions!B13)^3)*Assumptions!B6)-Assumptions!B7-Assumptions!B8*Assumptions!B9)*(1-Assumptions!B10))+((((Assumptions!B16*(1+Assumptions!B17)^3)*Assumptions!B18)+(-(Assumptions!B16*(1+Assumptions!B17)^3)*Assumptions!B19)-Assumptions!B20+(Assumptions!B34*D5))*(1-Assumptions!B10))+(Assumptions!B33*D5*(1-Assumptions!B10))+(((-Assumptions!B26*Assumptions!B27)+(-((A10*Assumptions!B29)/Assumptions!B30)))+(-((-Assumptions!B26*Assumptions!B27)+(-((A10*Assumptions!B29)/Assumptions!B30)))*Assumptions!B10)))/(Assumptions!B11+(A10*Assumptions!B25/Assumptions!B12)))-(((((Assumptions!B5*(1+Assumptions!B13)^3)*Assumptions!B6)-Assumptions!B7-Assumptions!B8*Assumptions!B9)*(1-Assumptions!B10))/Assumptions!B11))/(((((Assumptions!B5*(1+Assumptions!B13)^3)*Assumptions!B6)-Assumptions!B7-Assumptions!B8*Assumptions!B9)*(1-Assumptions!B10))/Assumptions!B11) -> 0.28698332 | E10: =(((((((Assumptions!B5*(1+Assumptions!B13)^3)*Assumptions!B6)-Assumptions!B7-Assumptions!B8*Assumptions!B9)*(1-Assumptions!B10))+((((Assumptions!B16*(1+Assumptions!B17)^3)*Assumptions!B18)+(-(Assumptions!B16*(1+Assumptions!B17)^3)*Assumptions!B19)-Assumptions!B20+(Assumptions!B34*E5))*(1-Assumptions!B10))+(Assumptions!B33*E5*(1-Assumptions!B10))+(((-Assumptions!B26*Assumptions!B27)+(-((A10*Assumptions!B29)/Assumptions!B30)))+(-((-Assumptions!B26*Assumptions!B27)+(-((A10*Assumptions!B29)/Assumptions!B30)))*Assumptions!B10)))/(Assumptions!B11+(A10*Assumptions!B25/Assumptions!B12)))-(((((Assumptions!B5*(1+Assumptions!B13)^3)*Assumptions!B6)-Assumptions!B7-Assumptions!B8*Assumptions!B9)*(1-Assumptions!B10))/Assumptions!B11))/(((((Assumptions!B5*(1+Assumptions!B13)^3)*Assumptions!B6)-Assumptions!B7-Assumptions!B8*Assumptions!B9)*(1-Assumptions!B10))/Assumptions!B11) -> 0.41929318 | F10: =(((((((Assumptions!B5*(1+Assumptions!B13)^3)*Assumptions!B6)-Assumptions!B7-Assumptions!B8*Assumptions!B9)*(1-Assumptions!B10))+((((Assumptions!B16*(1+Assumptions!B17)^3)*Assumptions!B18)+(-(Assumptions!B16*(1+Assumptions!B17)^3)*Assumptions!B19)-Assumptions!B20+(Assumptions!B34*F5))*(1-Assumptions!B10))+(Assumptions!B33*F5*(1-Assumptions!B10))+(((-Assumptions!B26*Assumptions!B27)+(-((A10*Assumptions!B29)/Assumptions!B30)))+(-((-Assumptions!B26*Assumptions!B27)+(-((A10*Assumptions!B29)/Assumptions!B30)))*Assumptions!B10)))/(Assumptions!B11+(A10*Assumptions!B25/Assumptions!B12)))-(((((Assumptions!B5*(1+Assumptions!B13)^3)*Assumptions!B6)-Assumptions!B7-Assumptions!B8*Assumptions!B9)*(1-Assumptions!B10))/Assumptions!B11))/(((((Assumptions!B5*(1+Assumptions!B13)^3)*Assumptions!B6)-Assumptions!B7-Assumptions!B8*Assumptions!B9)*(1-Assumptions!B10))/Assumptions!B11) -> 0.55160303
A11: 630 | B11: =(((((((Assumptions!B5*(1+Assumptions!B13)^3)*Assumptions!B6)-Assumptions!B7-Assumptions!B8*Assumptions!B9)*(1-Assumptions!B10))+((((Assumptions!B16*(1+Assumptions!B17)^3)*Assumptions!B18)+(-(Assumptions!B16*(1+Assumptions!B17)^3)*Assumptions!B19)-Assumptions!B20+(Assumptions!B34*B5))*(1-Assumptions!B10))+(Assumptions!B33*B5*(1-Assumptions!B10))+(((-Assumptions!B26*Assumptions!B27)+(-((A11*Assumptions!B29)/Assumptions!B30)))+(-((-Assumptions!B26*Assumptions!B27)+(-((A11*Assumptions!B29)/Assumptions!B30)))*Assumptions!B10)))/(Assumptions!B11+(A11*Assumptions!B25/Assumptions!B12)))-(((((Assumptions!B5*(1+Assumptions!B13)^3)*Assumptions!B6)-Assumptions!B7-Assumptions!B8*Assumptions!B9)*(1-Assumptions!B10))/Assumptions!B11))/(((((Assumptions!B5*(1+Assumptions!B13)^3)*Assumptions!B6)-Assumptions!B7-Assumptions!B8*Assumptions!B9)*(1-Assumptions!B10))/Assumptions!B11) -> 0.0093039555 | C11: =(((((((Assumptions!B5*(1+Assumptions!B13)^3)*Assumptions!B6)-Assumptions!B7-Assumptions!B8*Assumptions!B9)*(1-Assumptions!B10))+((((Assumptions!B16*(1+Assumptions!B17)^3)*Assumptions!B18)+(-(Assumptions!B16*(1+Assumptions!B17)^3)*Assumptions!B19)-Assumptions!B20+(Assumptions!B34*C5))*(1-Assumptions!B10))+(Assumptions!B33*C5*(1-Assumptions!B10))+(((-Assumptions!B26*Assumptions!B27)+(-((A11*Assumptions!B29)/Assumptions!B30)))+(-((-Assumptions!B26*Assumptions!B27)+(-((A11*Assumptions!B29)/Assumptions!B30)))*Assumptions!B10)))/(Assumptions!B11+(A11*Assumptions!B25/Assumptions!B12)))-(((((Assumptions!B5*(1+Assumptions!B13)^3)*Assumptions!B6)-Assumptions!B7-Assumptions!B8*Assumptions!B9)*(1-Assumptions!B10))/Assumptions!B11))/(((((Assumptions!B5*(1+Assumptions!B13)^3)*Assumptions!B6)-Assumptions!B7-Assumptions!B8*Assumptions!B9)*(1-Assumptions!B10))/Assumptions!B11) -> 0.1411424 | D11: =(((((((Assumptions!B5*(1+Assumptions!B13)^3)*Assumptions!B6)-Assumptions!B7-Assumptions!B8*Assumptions!B9)*(1-Assumptions!B10))+((((Assumptions!B16*(1+Assumptions!B17)^3)*Assumptions!B18)+(-(Assumptions!B16*(1+Assumptions!B17)^3)*Assumptions!B19)-Assumptions!B20+(Assumptions!B34*D5))*(1-Assumptions!B10))+(Assumptions!B33*D5*(1-Assumptions!B10))+(((-Assumptions!B26*Assumptions!B27)+(-((A11*Assumptions!B29)/Assumptions!B30)))+(-((-Assumptions!B26*Assumptions!B27)+(-((A11*Assumptions!B29)/Assumptions!B30)))*Assumptions!B10)))/(Assumptions!B11+(A11*Assumptions!B25/Assumptions!B12)))-(((((Assumptions!B5*(1+Assumptions!B13)^3)*Assumptions!B6)-Assumptions!B7-Assumptions!B8*Assumptions!B9)*(1-Assumptions!B10))/Assumptions!B11))/(((((Assumptions!B5*(1+Assumptions!B13)^3)*Assumptions!B6)-Assumptions!B7-Assumptions!B8*Assumptions!B9)*(1-Assumptions!B10))/Assumptions!B11) -> 0.27298084 | E11: =(((((((Assumptions!B5*(1+Assumptions!B13)^3)*Assumptions!B6)-Assumptions!B7-Assumptions!B8*Assumptions!B9)*(1-Assumptions!B10))+((((Assumptions!B16*(1+Assumptions!B17)^3)*Assumptions!B18)+(-(Assumptions!B16*(1+Assumptions!B17)^3)*Assumptions!B19)-Assumptions!B20+(Assumptions!B34*E5))*(1-Assumptions!B10))+(Assumptions!B33*E5*(1-Assumptions!B10))+(((-Assumptions!B26*Assumptions!B27)+(-((A11*Assumptions!B29)/Assumptions!B30)))+(-((-Assumptions!B26*Assumptions!B27)+(-((A11*Assumptions!B29)/Assumptions!B30)))*Assumptions!B10)))/(Assumptions!B11+(A11*Assumptions!B25/Assumptions!B12)))-(((((Assumptions!B5*(1+Assumptions!B13)^3)*Assumptions!B6)-Assumptions!B7-Assumptions!B8*Assumptions!B9)*(1-Assumptions!B10))/Assumptions!B11))/(((((Assumptions!B5*(1+Assumptions!B13)^3)*Assumptions!B6)-Assumptions!B7-Assumptions!B8*Assumptions!B9)*(1-Assumptions!B10))/Assumptions!B11) -> 0.40481928 | F11: =(((((((Assumptions!B5*(1+Assumptions!B13)^3)*Assumptions!B6)-Assumptions!B7-Assumptions!B8*Assumptions!B9)*(1-Assumptions!B10))+((((Assumptions!B16*(1+Assumptions!B17)^3)*Assumptions!B18)+(-(Assumptions!B16*(1+Assumptions!B17)^3)*Assumptions!B19)-Assumptions!B20+(Assumptions!B34*F5))*(1-Assumptions!B10))+(Assumptions!B33*F5*(1-Assumptions!B10))+(((-Assumptions!B26*Assumptions!B27)+(-((A11*Assumptions!B29)/Assumptions!B30)))+(-((-Assumptions!B26*Assumptions!B27)+(-((A11*Assumptions!B29)/Assumptions!B30)))*Assumptions!B10)))/(Assumptions!B11+(A11*Assumptions!B25/Assumptions!B12)))-(((((Assumptions!B5*(1+Assumptions!B13)^3)*Assumptions!B6)-Assumptions!B7-Assumptions!B8*Assumptions!B9)*(1-Assumptions!B10))/Assumptions!B11))/(((((Assumptions!B5*(1+Assumptions!B13)^3)*Assumptions!B6)-Assumptions!B7-Assumptions!B8*Assumptions!B9)*(1-Assumptions!B10))/Assumptions!B11) -> 0.53665772
A13: Bold Border = base case ($570M, 100% synergies)
A14: Color scale: red = dilutive · white = breakeven · green = accretive
A16: Year 1 Sensitivity
A17: Acq. Price / Syns realized | B17: 0 | C17: 0.25 | D17: 0.5 | E17: 0.75 | F17: 1
A18: 490 | B18: =((((((Assumptions!B5*(1+Assumptions!B13))*Assumptions!B6-Assumptions!B7-Assumptions!B8*Assumptions!B9)*(1-Assumptions!B10))+((((Assumptions!B16*(1+Assumptions!B17))*Assumptions!B18)+(-(Assumptions!B16*(1+Assumptions!B17))*Assumptions!B19)-Assumptions!B20+(Assumptions!B34*Assumptions!B35*0/Assumptions!B37)+(-Assumptions!B38))*(1-Assumptions!B10))+(Assumptions!B33*Assumptions!B35*0/Assumptions!B37*(1-Assumptions!B10))+(((-Assumptions!B26*Assumptions!B27)+(-((490*Assumptions!B29)/Assumptions!B30))+(-490*Assumptions!B28))+(-((-Assumptions!B26*Assumptions!B27)+(-((490*Assumptions!B29)/Assumptions!B30))+(-490*Assumptions!B28))*Assumptions!B10)))/(Assumptions!B11+(490*Assumptions!B25/Assumptions!B12)))-((((Assumptions!B5*(1+Assumptions!B13))*Assumptions!B6-Assumptions!B7-Assumptions!B8*Assumptions!B9)*(1-Assumptions!B10))/Assumptions!B11))/((((Assumptions!B5*(1+Assumptions!B13))*Assumptions!B6-Assumptions!B7-Assumptions!B8*Assumptions!B9)*(1-Assumptions!B10))/Assumptions!B11) -> -0.51305714 | C18: =((((((Assumptions!B5*(1+Assumptions!B13))*Assumptions!B6-Assumptions!B7-Assumptions!B8*Assumptions!B9)*(1-Assumptions!B10))+((((Assumptions!B16*(1+Assumptions!B17))*Assumptions!B18)+(-(Assumptions!B16*(1+Assumptions!B17))*Assumptions!B19)-Assumptions!B20+(Assumptions!B34*Assumptions!B35*0.25/Assumptions!B37)+(-Assumptions!B38))*(1-Assumptions!B10))+(Assumptions!B33*Assumptions!B35*0.25/Assumptions!B37*(1-Assumptions!B10))+(((-Assumptions!B26*Assumptions!B27)+(-((490*Assumptions!B29)/Assumptions!B30))+(-490*Assumptions!B28))+(-((-Assumptions!B26*Assumptions!B27)+(-((490*Assumptions!B29)/Assumptions!B30))+(-490*Assumptions!B28))*Assumptions!B10)))/(Assumptions!B11+(490*Assumptions!B25/Assumptions!B12)))-((((Assumptions!B5*(1+Assumptions!B13))*Assumptions!B6-Assumptions!B7-Assumptions!B8*Assumptions!B9)*(1-Assumptions!B10))/Assumptions!B11))/((((Assumptions!B5*(1+Assumptions!B13))*Assumptions!B6-Assumptions!B7-Assumptions!B8*Assumptions!B9)*(1-Assumptions!B10))/Assumptions!B11) -> -0.43725432 | D18: =((((((Assumptions!B5*(1+Assumptions!B13))*Assumptions!B6-Assumptions!B7-Assumptions!B8*Assumptions!B9)*(1-Assumptions!B10))+((((Assumptions!B16*(1+Assumptions!B17))*Assumptions!B18)+(-(Assumptions!B16*(1+Assumptions!B17))*Assumptions!B19)-Assumptions!B20+(Assumptions!B34*Assumptions!B35*0.5/Assumptions!B37)+(-Assumptions!B38))*(1-Assumptions!B10))+(Assumptions!B33*Assumptions!B35*0.5/Assumptions!B37*(1-Assumptions!B10))+(((-Assumptions!B26*Assumptions!B27)+(-((490*Assumptions!B29)/Assumptions!B30))+(-490*Assumptions!B28))+(-((-Assumptions!B26*Assumptions!B27)+(-((490*Assumptions!B29)/Assumptions!B30))+(-490*Assumptions!B28))*Assumptions!B10)))/(Assumptions!B11+(490*Assumptions!B25/Assumptions!B12)))-((((Assumptions!B5*(1+Assumptions!B13))*Assumptions!B6-Assumptions!B7-Assumptions!B8*Assumptions!B9)*(1-Assumptions!B10))/Assumptions!B11))/((((Assumptions!B5*(1+Assumptions!B13))*Assumptions!B6-Assumptions!B7-Assumptions!B8*Assumptions!B9)*(1-Assumptions!B10))/Assumptions!B11) -> -0.3614515 | E18: =((((((Assumptions!B5*(1+Assumptions!B13))*Assumptions!B6-Assumptions!B7-Assumptions!B8*Assumptions!B9)*(1-Assumptions!B10))+((((Assumptions!B16*(1+Assumptions!B17))*Assumptions!B18)+(-(Assumptions!B16*(1+Assumptions!B17))*Assumptions!B19)-Assumptions!B20+(Assumptions!B34*Assumptions!B35*0.75/Assumptions!B37)+(-Assumptions!B38))*(1-Assumptions!B10))+(Assumptions!B33*Assumptions!B35*0.75/Assumptions!B37*(1-Assumptions!B10))+(((-Assumptions!B26*Assumptions!B27)+(-((490*Assumptions!B29)/Assumptions!B30))+(-490*Assumptions!B28))+(-((-Assumptions!B26*Assumptions!B27)+(-((490*Assumptions!B29)/Assumptions!B30))+(-490*Assumptions!B28))*Assumptions!B10)))/(Assumptions!B11+(490*Assumptions!B25/Assumptions!B12)))-((((Assumptions!B5*(1+Assumptions!B13))*Assumptions!B6-Assumptions!B7-Assumptions!B8*Assumptions!B9)*(1-Assumptions!B10))/Assumptions!B11))/((((Assumptions!B5*(1+Assumptions!B13))*Assumptions!B6-Assumptions!B7-Assumptions!B8*Assumptions!B9)*(1-Assumptions!B10))/Assumptions!B11) -> -0.28564869 | F18: =((((((Assumptions!B5*(1+Assumptions!B13))*Assumptions!B6-Assumptions!B7-Assumptions!B8*Assumptions!B9)*(1-Assumptions!B10))+((((Assumptions!B16*(1+Assumptions!B17))*Assumptions!B18)+(-(Assumptions!B16*(1+Assumptions!B17))*Assumptions!B19)-Assumptions!B20+(Assumptions!B34*Assumptions!B35*1/Assumptions!B37)+(-Assumptions!B38))*(1-Assumptions!B10))+(Assumptions!B33*Assumptions!B35*1/Assumptions!B37*(1-Assumptions!B10))+(((-Assumptions!B26*Assumptions!B27)+(-((490*Assumptions!B29)/Assumptions!B30))+(-490*Assumptions!B28))+(-((-Assumptions!B26*Assumptions!B27)+(-((490*Assumptions!B29)/Assumptions!B30))+(-490*Assumptions!B28))*Assumptions!B10)))/(Assumptions!B11+(490*Assumptions!B25/Assumptions!B12)))-((((Assumptions!B5*(1+Assumptions!B13))*Assumptions!B6-Assumptions!B7-Assumptions!B8*Assumptions!B9)*(1-Assumptions!B10))/Assumptions!B11))/((((Assumptions!B5*(1+Assumptions!B13))*Assumptions!B6-Assumptions!B7-Assumptions!B8*Assumptions!B9)*(1-Assumptions!B10))/Assumptions!B11) -> -0.20984587
A19: 520 | B19: =((((((Assumptions!B5*(1+Assumptions!B13))*Assumptions!B6-Assumptions!B7-Assumptions!B8*Assumptions!B9)*(1-Assumptions!B10))+((((Assumptions!B16*(1+Assumptions!B17))*Assumptions!B18)+(-(Assumptions!B16*(1+Assumptions!B17))*Assumptions!B19)-Assumptions!B20+(Assumptions!B34*Assumptions!B35*0/Assumptions!B37)+(-Assumptions!B38))*(1-Assumptions!B10))+(Assumptions!B33*Assumptions!B35*0/Assumptions!B37*(1-Assumptions!B10))+(((-Assumptions!B26*Assumptions!B27)+(-((520*Assumptions!B29)/Assumptions!B30))+(-520*Assumptions!B28))+(-((-Assumptions!B26*Assumptions!B27)+(-((520*Assumptions!B29)/Assumptions!B30))+(-520*Assumptions!B28))*Assumptions!B10)))/(Assumptions!B11+(520*Assumptions!B25/Assumptions!B12)))-((((Assumptions!B5*(1+Assumptions!B13))*Assumptions!B6-Assumptions!B7-Assumptions!B8*Assumptions!B9)*(1-Assumptions!B10))/Assumptions!B11))/((((Assumptions!B5*(1+Assumptions!B13))*Assumptions!B6-Assumptions!B7-Assumptions!B8*Assumptions!B9)*(1-Assumptions!B10))/Assumptions!B11) -> -0.53207886 | C19: =((((((Assumptions!B5*(1+Assumptions!B13))*Assumptions!B6-Assumptions!B7-Assumptions!B8*Assumptions!B9)*(1-Assumptions!B10))+((((Assumptions!B16*(1+Assumptions!B17))*Assumptions!B18)+(-(Assumptions!B16*(1+Assumptions!B17))*Assumptions!B19)-Assumptions!B20+(Assumptions!B34*Assumptions!B35*0.25/Assumptions!B37)+(-Assumptions!B38))*(1-Assumptions!B10))+(Assumptions!B33*Assumptions!B35*0.25/Assumptions!B37*(1-Assumptions!B10))+(((-Assumptions!B26*Assumptions!B27)+(-((520*Assumptions!B29)/Assumptions!B30))+(-520*Assumptions!B28))+(-((-Assumptions!B26*Assumptions!B27)+(-((520*Assumptions!B29)/Assumptions!B30))+(-520*Assumptions!B28))*Assumptions!B10)))/(Assumptions!B11+(520*Assumptions!B25/Assumptions!B12)))-((((Assumptions!B5*(1+Assumptions!B13))*Assumptions!B6-Assumptions!B7-Assumptions!B8*Assumptions!B9)*(1-Assumptions!B10))/Assumptions!B11))/((((Assumptions!B5*(1+Assumptions!B13))*Assumptions!B6-Assumptions!B7-Assumptions!B8*Assumptions!B9)*(1-Assumptions!B10))/Assumptions!B11) -> -0.4565497 | D19: =((((((Assumptions!B5*(1+Assumptions!B13))*Assumptions!B6-Assumptions!B7-Assumptions!B8*Assumptions!B9)*(1-Assumptions!B10))+((((Assumptions!B16*(1+Assumptions!B17))*Assumptions!B18)+(-(Assumptions!B16*(1+Assumptions!B17))*Assumptions!B19)-Assumptions!B20+(Assumptions!B34*Assumptions!B35*0.5/Assumptions!B37)+(-Assumptions!B38))*(1-Assumptions!B10))+(Assumptions!B33*Assumptions!B35*0.5/Assumptions!B37*(1-Assumptions!B10))+(((-Assumptions!B26*Assumptions!B27)+(-((520*Assumptions!B29)/Assumptions!B30))+(-520*Assumptions!B28))+(-((-Assumptions!B26*Assumptions!B27)+(-((520*Assumptions!B29)/Assumptions!B30))+(-520*Assumptions!B28))*Assumptions!B10)))/(Assumptions!B11+(520*Assumptions!B25/Assumptions!B12)))-((((Assumptions!B5*(1+Assumptions!B13))*Assumptions!B6-Assumptions!B7-Assumptions!B8*Assumptions!B9)*(1-Assumptions!B10))/Assumptions!B11))/((((Assumptions!B5*(1+Assumptions!B13))*Assumptions!B6-Assumptions!B7-Assumptions!B8*Assumptions!B9)*(1-Assumptions!B10))/Assumptions!B11) -> -0.38102054 | E19: =((((((Assumptions!B5*(1+Assumptions!B13))*Assumptions!B6-Assumptions!B7-Assumptions!B8*Assumptions!B9)*(1-Assumptions!B10))+((((Assumptions!B16*(1+Assumptions!B17))*Assumptions!B18)+(-(Assumptions!B16*(1+Assumptions!B17))*Assumptions!B19)-Assumptions!B20+(Assumptions!B34*Assumptions!B35*0.75/Assumptions!B37)+(-Assumptions!B38))*(1-Assumptions!B10))+(Assumptions!B33*Assumptions!B35*0.75/Assumptions!B37*(1-Assumptions!B10))+(((-Assumptions!B26*Assumptions!B27)+(-((520*Assumptions!B29)/Assumptions!B30))+(-520*Assumptions!B28))+(-((-Assumptions!B26*Assumptions!B27)+(-((520*Assumptions!B29)/Assumptions!B30))+(-520*Assumptions!B28))*Assumptions!B10)))/(Assumptions!B11+(520*Assumptions!B25/Assumptions!B12)))-((((Assumptions!B5*(1+Assumptions!B13))*Assumptions!B6-Assumptions!B7-Assumptions!B8*Assumptions!B9)*(1-Assumptions!B10))/Assumptions!B11))/((((Assumptions!B5*(1+Assumptions!B13))*Assumptions!B6-Assumptions!B7-Assumptions!B8*Assumptions!B9)*(1-Assumptions!B10))/Assumptions!B11) -> -0.30549138 | F19: =((((((Assumptions!B5*(1+Assumptions!B13))*Assumptions!B6-Assumptions!B7-Assumptions!B8*Assumptions!B9)*(1-Assumptions!B10))+((((Assumptions!B16*(1+Assumptions!B17))*Assumptions!B18)+(-(Assumptions!B16*(1+Assumptions!B17))*Assumptions!B19)-Assumptions!B20+(Assumptions!B34*Assumptions!B35*1/Assumptions!B37)+(-Assumptions!B38))*(1-Assumptions!B10))+(Assumptions!B33*Assumptions!B35*1/Assumptions!B37*(1-Assumptions!B10))+(((-Assumptions!B26*Assumptions!B27)+(-((520*Assumptions!B29)/Assumptions!B30))+(-520*Assumptions!B28))+(-((-Assumptions!B26*Assumptions!B27)+(-((520*Assumptions!B29)/Assumptions!B30))+(-520*Assumptions!B28))*Assumptions!B10)))/(Assumptions!B11+(520*Assumptions!B25/Assumptions!B12)))-((((Assumptions!B5*(1+Assumptions!B13))*Assumptions!B6-Assumptions!B7-Assumptions!B8*Assumptions!B9)*(1-Assumptions!B10))/Assumptions!B11))/((((Assumptions!B5*(1+Assumptions!B13))*Assumptions!B6-Assumptions!B7-Assumptions!B8*Assumptions!B9)*(1-Assumptions!B10))/Assumptions!B11) -> -0.22996222
A20: 550 | B20: =((((((Assumptions!B5*(1+Assumptions!B13))*Assumptions!B6-Assumptions!B7-Assumptions!B8*Assumptions!B9)*(1-Assumptions!B10))+((((Assumptions!B16*(1+Assumptions!B17))*Assumptions!B18)+(-(Assumptions!B16*(1+Assumptions!B17))*Assumptions!B19)-Assumptions!B20+(Assumptions!B34*Assumptions!B35*0/Assumptions!B37)+(-Assumptions!B38))*(1-Assumptions!B10))+(Assumptions!B33*Assumptions!B35*0/Assumptions!B37*(1-Assumptions!B10))+(((-Assumptions!B26*Assumptions!B27)+(-((550*Assumptions!B29)/Assumptions!B30))+(-550*Assumptions!B28))+(-((-Assumptions!B26*Assumptions!B27)+(-((550*Assumptions!B29)/Assumptions!B30))+(-550*Assumptions!B28))*Assumptions!B10)))/(Assumptions!B11+(550*Assumptions!B25/Assumptions!B12)))-((((Assumptions!B5*(1+Assumptions!B13))*Assumptions!B6-Assumptions!B7-Assumptions!B8*Assumptions!B9)*(1-Assumptions!B10))/Assumptions!B11))/((((Assumptions!B5*(1+Assumptions!B13))*Assumptions!B6-Assumptions!B7-Assumptions!B8*Assumptions!B9)*(1-Assumptions!B10))/Assumptions!B11) -> -0.55096374 | C20: =((((((Assumptions!B5*(1+Assumptions!B13))*Assumptions!B6-Assumptions!B7-Assumptions!B8*Assumptions!B9)*(1-Assumptions!B10))+((((Assumptions!B16*(1+Assumptions!B17))*Assumptions!B18)+(-(Assumptions!B16*(1+Assumptions!B17))*Assumptions!B19)-Assumptions!B20+(Assumptions!B34*Assumptions!B35*0.25/Assumptions!B37)+(-Assumptions!B38))*(1-Assumptions!B10))+(Assumptions!B33*Assumptions!B35*0.25/Assumptions!B37*(1-Assumptions!B10))+(((-Assumptions!B26*Assumptions!B27)+(-((550*Assumptions!B29)/Assumptions!B30))+(-550*Assumptions!B28))+(-((-Assumptions!B26*Assumptions!B27)+(-((550*Assumptions!B29)/Assumptions!B30))+(-550*Assumptions!B28))*Assumptions!B10)))/(Assumptions!B11+(550*Assumptions!B25/Assumptions!B12)))-((((Assumptions!B5*(1+Assumptions!B13))*Assumptions!B6-Assumptions!B7-Assumptions!B8*Assumptions!B9)*(1-Assumptions!B10))/Assumptions!B11))/((((Assumptions!B5*(1+Assumptions!B13))*Assumptions!B6-Assumptions!B7-Assumptions!B8*Assumptions!B9)*(1-Assumptions!B10))/Assumptions!B11) -> -0.47570627 | D20: =((((((Assumptions!B5*(1+Assumptions!B13))*Assumptions!B6-Assumptions!B7-Assumptions!B8*Assumptions!B9)*(1-Assumptions!B10))+((((Assumptions!B16*(1+Assumptions!B17))*Assumptions!B18)+(-(Assumptions!B16*(1+Assumptions!B17))*Assumptions!B19)-Assumptions!B20+(Assumptions!B34*Assumptions!B35*0.5/Assumptions!B37)+(-Assumptions!B38))*(1-Assumptions!B10))+(Assumptions!B33*Assumptions!B35*0.5/Assumptions!B37*(1-Assumptions!B10))+(((-Assumptions!B26*Assumptions!B27)+(-((550*Assumptions!B29)/Assumptions!B30))+(-550*Assumptions!B28))+(-((-Assumptions!B26*Assumptions!B27)+(-((550*Assumptions!B29)/Assumptions!B30))+(-550*Assumptions!B28))*Assumptions!B10)))/(Assumptions!B11+(550*Assumptions!B25/Assumptions!B12)))-((((Assumptions!B5*(1+Assumptions!B13))*Assumptions!B6-Assumptions!B7-Assumptions!B8*Assumptions!B9)*(1-Assumptions!B10))/Assumptions!B11))/((((Assumptions!B5*(1+Assumptions!B13))*Assumptions!B6-Assumptions!B7-Assumptions!B8*Assumptions!B9)*(1-Assumptions!B10))/Assumptions!B11) -> -0.40044879 | E20: =((((((Assumptions!B5*(1+Assumptions!B13))*Assumptions!B6-Assumptions!B7-Assumptions!B8*Assumptions!B9)*(1-Assumptions!B10))+((((Assumptions!B16*(1+Assumptions!B17))*Assumptions!B18)+(-(Assumptions!B16*(1+Assumptions!B17))*Assumptions!B19)-Assumptions!B20+(Assumptions!B34*Assumptions!B35*0.75/Assumptions!B37)+(-Assumptions!B38))*(1-Assumptions!B10))+(Assumptions!B33*Assumptions!B35*0.75/Assumptions!B37*(1-Assumptions!B10))+(((-Assumptions!B26*Assumptions!B27)+(-((550*Assumptions!B29)/Assumptions!B30))+(-550*Assumptions!B28))+(-((-Assumptions!B26*Assumptions!B27)+(-((550*Assumptions!B29)/Assumptions!B30))+(-550*Assumptions!B28))*Assumptions!B10)))/(Assumptions!B11+(550*Assumptions!B25/Assumptions!B12)))-((((Assumptions!B5*(1+Assumptions!B13))*Assumptions!B6-Assumptions!B7-Assumptions!B8*Assumptions!B9)*(1-Assumptions!B10))/Assumptions!B11))/((((Assumptions!B5*(1+Assumptions!B13))*Assumptions!B6-Assumptions!B7-Assumptions!B8*Assumptions!B9)*(1-Assumptions!B10))/Assumptions!B11) -> -0.32519132 | F20: =((((((Assumptions!B5*(1+Assumptions!B13))*Assumptions!B6-Assumptions!B7-Assumptions!B8*Assumptions!B9)*(1-Assumptions!B10))+((((Assumptions!B16*(1+Assumptions!B17))*Assumptions!B18)+(-(Assumptions!B16*(1+Assumptions!B17))*Assumptions!B19)-Assumptions!B20+(Assumptions!B34*Assumptions!B35*1/Assumptions!B37)+(-Assumptions!B38))*(1-Assumptions!B10))+(Assumptions!B33*Assumptions!B35*1/Assumptions!B37*(1-Assumptions!B10))+(((-Assumptions!B26*Assumptions!B27)+(-((550*Assumptions!B29)/Assumptions!B30))+(-550*Assumptions!B28))+(-((-Assumptions!B26*Assumptions!B27)+(-((550*Assumptions!B29)/Assumptions!B30))+(-550*Assumptions!B28))*Assumptions!B10)))/(Assumptions!B11+(550*Assumptions!B25/Assumptions!B12)))-((((Assumptions!B5*(1+Assumptions!B13))*Assumptions!B6-Assumptions!B7-Assumptions!B8*Assumptions!B9)*(1-Assumptions!B10))/Assumptions!B11))/((((Assumptions!B5*(1+Assumptions!B13))*Assumptions!B6-Assumptions!B7-Assumptions!B8*Assumptions!B9)*(1-Assumptions!B10))/Assumptions!B11) -> -0.24993385
A21: 570 | B21: =((((((Assumptions!B5*(1+Assumptions!B13))*Assumptions!B6-Assumptions!B7-Assumptions!B8*Assumptions!B9)*(1-Assumptions!B10))+((((Assumptions!B16*(1+Assumptions!B17))*Assumptions!B18)+(-(Assumptions!B16*(1+Assumptions!B17))*Assumptions!B19)-Assumptions!B20+(Assumptions!B34*Assumptions!B35*0/Assumptions!B37)+(-Assumptions!B38))*(1-Assumptions!B10))+(Assumptions!B33*Assumptions!B35*0/Assumptions!B37*(1-Assumptions!B10))+(((-Assumptions!B26*Assumptions!B27)+(-((570*Assumptions!B29)/Assumptions!B30))+(-570*Assumptions!B28))+(-((-Assumptions!B26*Assumptions!B27)+(-((570*Assumptions!B29)/Assumptions!B30))+(-570*Assumptions!B28))*Assumptions!B10)))/(Assumptions!B11+(570*Assumptions!B25/Assumptions!B12)))-((((Assumptions!B5*(1+Assumptions!B13))*Assumptions!B6-Assumptions!B7-Assumptions!B8*Assumptions!B9)*(1-Assumptions!B10))/Assumptions!B11))/((((Assumptions!B5*(1+Assumptions!B13))*Assumptions!B6-Assumptions!B7-Assumptions!B8*Assumptions!B9)*(1-Assumptions!B10))/Assumptions!B11) -> -0.56347836 | C21: =((((((Assumptions!B5*(1+Assumptions!B13))*Assumptions!B6-Assumptions!B7-Assumptions!B8*Assumptions!B9)*(1-Assumptions!B10))+((((Assumptions!B16*(1+Assumptions!B17))*Assumptions!B18)+(-(Assumptions!B16*(1+Assumptions!B17))*Assumptions!B19)-Assumptions!B20+(Assumptions!B34*Assumptions!B35*0.25/Assumptions!B37)+(-Assumptions!B38))*(1-Assumptions!B10))+(Assumptions!B33*Assumptions!B35*0.25/Assumptions!B37*(1-Assumptions!B10))+(((-Assumptions!B26*Assumptions!B27)+(-((570*Assumptions!B29)/Assumptions!B30))+(-570*Assumptions!B28))+(-((-Assumptions!B26*Assumptions!B27)+(-((570*Assumptions!B29)/Assumptions!B30))+(-570*Assumptions!B28))*Assumptions!B10)))/(Assumptions!B11+(570*Assumptions!B25/Assumptions!B12)))-((((Assumptions!B5*(1+Assumptions!B13))*Assumptions!B6-Assumptions!B7-Assumptions!B8*Assumptions!B9)*(1-Assumptions!B10))/Assumptions!B11))/((((Assumptions!B5*(1+Assumptions!B13))*Assumptions!B6-Assumptions!B7-Assumptions!B8*Assumptions!B9)*(1-Assumptions!B10))/Assumptions!B11) -> -0.48840093 | D21: =((((((Assumptions!B5*(1+Assumptions!B13))*Assumptions!B6-Assumptions!B7-Assumptions!B8*Assumptions!B9)*(1-Assumptions!B10))+((((Assumptions!B16*(1+Assumptions!B17))*Assumptions!B18)+(-(Assumptions!B16*(1+Assumptions!B17))*Assumptions!B19)-Assumptions!B20+(Assumptions!B34*Assumptions!B35*0.5/Assumptions!B37)+(-Assumptions!B38))*(1-Assumptions!B10))+(Assumptions!B33*Assumptions!B35*0.5/Assumptions!B37*(1-Assumptions!B10))+(((-Assumptions!B26*Assumptions!B27)+(-((570*Assumptions!B29)/Assumptions!B30))+(-570*Assumptions!B28))+(-((-Assumptions!B26*Assumptions!B27)+(-((570*Assumptions!B29)/Assumptions!B30))+(-570*Assumptions!B28))*Assumptions!B10)))/(Assumptions!B11+(570*Assumptions!B25/Assumptions!B12)))-((((Assumptions!B5*(1+Assumptions!B13))*Assumptions!B6-Assumptions!B7-Assumptions!B8*Assumptions!B9)*(1-Assumptions!B10))/Assumptions!B11))/((((Assumptions!B5*(1+Assumptions!B13))*Assumptions!B6-Assumptions!B7-Assumptions!B8*Assumptions!B9)*(1-Assumptions!B10))/Assumptions!B11) -> -0.4133235 | E21: =((((((Assumptions!B5*(1+Assumptions!B13))*Assumptions!B6-Assumptions!B7-Assumptions!B8*Assumptions!B9)*(1-Assumptions!B10))+((((Assumptions!B16*(1+Assumptions!B17))*Assumptions!B18)+(-(Assumptions!B16*(1+Assumptions!B17))*Assumptions!B19)-Assumptions!B20+(Assumptions!B34*Assumptions!B35*0.75/Assumptions!B37)+(-Assumptions!B38))*(1-Assumptions!B10))+(Assumptions!B33*Assumptions!B35*0.75/Assumptions!B37*(1-Assumptions!B10))+(((-Assumptions!B26*Assumptions!B27)+(-((570*Assumptions!B29)/Assumptions!B30))+(-570*Assumptions!B28))+(-((-Assumptions!B26*Assumptions!B27)+(-((570*Assumptions!B29)/Assumptions!B30))+(-570*Assumptions!B28))*Assumptions!B10)))/(Assumptions!B11+(570*Assumptions!B25/Assumptions!B12)))-((((Assumptions!B5*(1+Assumptions!B13))*Assumptions!B6-Assumptions!B7-Assumptions!B8*Assumptions!B9)*(1-Assumptions!B10))/Assumptions!B11))/((((Assumptions!B5*(1+Assumptions!B13))*Assumptions!B6-Assumptions!B7-Assumptions!B8*Assumptions!B9)*(1-Assumptions!B10))/Assumptions!B11) -> -0.33824607 | F21: =((((((Assumptions!B5*(1+Assumptions!B13))*Assumptions!B6-Assumptions!B7-Assumptions!B8*Assumptions!B9)*(1-Assumptions!B10))+((((Assumptions!B16*(1+Assumptions!B17))*Assumptions!B18)+(-(Assumptions!B16*(1+Assumptions!B17))*Assumptions!B19)-Assumptions!B20+(Assumptions!B34*Assumptions!B35*1/Assumptions!B37)+(-Assumptions!B38))*(1-Assumptions!B10))+(Assumptions!B33*Assumptions!B35*1/Assumptions!B37*(1-Assumptions!B10))+(((-Assumptions!B26*Assumptions!B27)+(-((570*Assumptions!B29)/Assumptions!B30))+(-570*Assumptions!B28))+(-((-Assumptions!B26*Assumptions!B27)+(-((570*Assumptions!B29)/Assumptions!B30))+(-570*Assumptions!B28))*Assumptions!B10)))/(Assumptions!B11+(570*Assumptions!B25/Assumptions!B12)))-((((Assumptions!B5*(1+Assumptions!B13))*Assumptions!B6-Assumptions!B7-Assumptions!B8*Assumptions!B9)*(1-Assumptions!B10))/Assumptions!B11))/((((Assumptions!B5*(1+Assumptions!B13))*Assumptions!B6-Assumptions!B7-Assumptions!B8*Assumptions!B9)*(1-Assumptions!B10))/Assumptions!B11) -> -0.26316863
A22: 600 | B22: =((((((Assumptions!B5*(1+Assumptions!B13))*Assumptions!B6-Assumptions!B7-Assumptions!B8*Assumptions!B9)*(1-Assumptions!B10))+((((Assumptions!B16*(1+Assumptions!B17))*Assumptions!B18)+(-(Assumptions!B16*(1+Assumptions!B17))*Assumptions!B19)-Assumptions!B20+(Assumptions!B34*Assumptions!B35*0/Assumptions!B37)+(-Assumptions!B38))*(1-Assumptions!B10))+(Assumptions!B33*Assumptions!B35*0/Assumptions!B37*(1-Assumptions!B10))+(((-Assumptions!B26*Assumptions!B27)+(-((600*Assumptions!B29)/Assumptions!B30))+(-600*Assumptions!B28))+(-((-Assumptions!B26*Assumptions!B27)+(-((600*Assumptions!B29)/Assumptions!B30))+(-600*Assumptions!B28))*Assumptions!B10)))/(Assumptions!B11+(600*Assumptions!B25/Assumptions!B12)))-((((Assumptions!B5*(1+Assumptions!B13))*Assumptions!B6-Assumptions!B7-Assumptions!B8*Assumptions!B9)*(1-Assumptions!B10))/Assumptions!B11))/((((Assumptions!B5*(1+Assumptions!B13))*Assumptions!B6-Assumptions!B7-Assumptions!B8*Assumptions!B9)*(1-Assumptions!B10))/Assumptions!B11) -> -0.58213842 | C22: =((((((Assumptions!B5*(1+Assumptions!B13))*Assumptions!B6-Assumptions!B7-Assumptions!B8*Assumptions!B9)*(1-Assumptions!B10))+((((Assumptions!B16*(1+Assumptions!B17))*Assumptions!B18)+(-(Assumptions!B16*(1+Assumptions!B17))*Assumptions!B19)-Assumptions!B20+(Assumptions!B34*Assumptions!B35*0.25/Assumptions!B37)+(-Assumptions!B38))*(1-Assumptions!B10))+(Assumptions!B33*Assumptions!B35*0.25/Assumptions!B37*(1-Assumptions!B10))+(((-Assumptions!B26*Assumptions!B27)+(-((600*Assumptions!B29)/Assumptions!B30))+(-600*Assumptions!B28))+(-((-Assumptions!B26*Assumptions!B27)+(-((600*Assumptions!B29)/Assumptions!B30))+(-600*Assumptions!B28))*Assumptions!B10)))/(Assumptions!B11+(600*Assumptions!B25/Assumptions!B12)))-((((Assumptions!B5*(1+Assumptions!B13))*Assumptions!B6-Assumptions!B7-Assumptions!B8*Assumptions!B9)*(1-Assumptions!B10))/Assumptions!B11))/((((Assumptions!B5*(1+Assumptions!B13))*Assumptions!B6-Assumptions!B7-Assumptions!B8*Assumptions!B9)*(1-Assumptions!B10))/Assumptions!B11) -> -0.50732944 | D22: =((((((Assumptions!B5*(1+Assumptions!B13))*Assumptions!B6-Assumptions!B7-Assumptions!B8*Assumptions!B9)*(1-Assumptions!B10))+((((Assumptions!B16*(1+Assumptions!B17))*Assumptions!B18)+(-(Assumptions!B16*(1+Assumptions!B17))*Assumptions!B19)-Assumptions!B20+(Assumptions!B34*Assumptions!B35*0.5/Assumptions!B37)+(-Assumptions!B38))*(1-Assumptions!B10))+(Assumptions!B33*Assumptions!B35*0.5/Assumptions!B37*(1-Assumptions!B10))+(((-Assumptions!B26*Assumptions!B27)+(-((600*Assumptions!B29)/Assumptions!B30))+(-600*Assumptions!B28))+(-((-Assumptions!B26*Assumptions!B27)+(-((600*Assumptions!B29)/Assumptions!B30))+(-600*Assumptions!B28))*Assumptions!B10)))/(Assumptions!B11+(600*Assumptions!B25/Assumptions!B12)))-((((Assumptions!B5*(1+Assumptions!B13))*Assumptions!B6-Assumptions!B7-Assumptions!B8*Assumptions!B9)*(1-Assumptions!B10))/Assumptions!B11))/((((Assumptions!B5*(1+Assumptions!B13))*Assumptions!B6-Assumptions!B7-Assumptions!B8*Assumptions!B9)*(1-Assumptions!B10))/Assumptions!B11) -> -0.43252046 | E22: =((((((Assumptions!B5*(1+Assumptions!B13))*Assumptions!B6-Assumptions!B7-Assumptions!B8*Assumptions!B9)*(1-Assumptions!B10))+((((Assumptions!B16*(1+Assumptions!B17))*Assumptions!B18)+(-(Assumptions!B16*(1+Assumptions!B17))*Assumptions!B19)-Assumptions!B20+(Assumptions!B34*Assumptions!B35*0.75/Assumptions!B37)+(-Assumptions!B38))*(1-Assumptions!B10))+(Assumptions!B33*Assumptions!B35*0.75/Assumptions!B37*(1-Assumptions!B10))+(((-Assumptions!B26*Assumptions!B27)+(-((600*Assumptions!B29)/Assumptions!B30))+(-600*Assumptions!B28))+(-((-Assumptions!B26*Assumptions!B27)+(-((600*Assumptions!B29)/Assumptions!B30))+(-600*Assumptions!B28))*Assumptions!B10)))/(Assumptions!B11+(600*Assumptions!B25/Assumptions!B12)))-((((Assumptions!B5*(1+Assumptions!B13))*Assumptions!B6-Assumptions!B7-Assumptions!B8*Assumptions!B9)*(1-Assumptions!B10))/Assumptions!B11))/((((Assumptions!B5*(1+Assumptions!B13))*Assumptions!B6-Assumptions!B7-Assumptions!B8*Assumptions!B9)*(1-Assumptions!B10))/Assumptions!B11) -> -0.35771148 | F22: =((((((Assumptions!B5*(1+Assumptions!B13))*Assumptions!B6-Assumptions!B7-Assumptions!B8*Assumptions!B9)*(1-Assumptions!B10))+((((Assumptions!B16*(1+Assumptions!B17))*Assumptions!B18)+(-(Assumptions!B16*(1+Assumptions!B17))*Assumptions!B19)-Assumptions!B20+(Assumptions!B34*Assumptions!B35*1/Assumptions!B37)+(-Assumptions!B38))*(1-Assumptions!B10))+(Assumptions!B33*Assumptions!B35*1/Assumptions!B37*(1-Assumptions!B10))+(((-Assumptions!B26*Assumptions!B27)+(-((600*Assumptions!B29)/Assumptions!B30))+(-600*Assumptions!B28))+(-((-Assumptions!B26*Assumptions!B27)+(-((600*Assumptions!B29)/Assumptions!B30))+(-600*Assumptions!B28))*Assumptions!B10)))/(Assumptions!B11+(600*Assumptions!B25/Assumptions!B12)))-((((Assumptions!B5*(1+Assumptions!B13))*Assumptions!B6-Assumptions!B7-Assumptions!B8*Assumptions!B9)*(1-Assumptions!B10))/Assumptions!B11))/((((Assumptions!B5*(1+Assumptions!B13))*Assumptions!B6-Assumptions!B7-Assumptions!B8*Assumptions!B9)*(1-Assumptions!B10))/Assumptions!B11) -> -0.28290251
